<?xml version="1.0" ?>
<!-- =================================================================================== -->
<!-- |    This document was autogenerated by xacro from smartcar.xacro                 | -->
<!-- |    EDITING THIS FILE BY HAND IS NOT RECOMMENDED                                 | -->
<!-- =================================================================================== -->
<robot name="smartcar" xmlns:body="http://playerstage.sourceforge.net/gazebo/xmlschema/#body" xmlns:controller="http://playerstage.sourceforge.net/gazebo/xmlschema/#controller" xmlns:gazebo="http://playerstage.sourceforge.net/gazebo/xmlschema/#gz" xmlns:geom="http://playerstage.sourceforge.net/gazebo/xmlschema/#geom" xmlns:interface="http://playerstage.sourceforge.net/gazebo/xmlschema/#interface" xmlns:joint="http://playerstage.sourceforge.net/gazebo/xmlschema/#joint" xmlns:model="http://playerstage.sourceforge.net/gazebo/xmlschema/#model" xmlns:physics="http://playerstage.sourceforge.net/gazebo/xmlschema/#physics" xmlns:renderable="http://playerstage.sourceforge.net/gazebo/xmlschema/#renderable" xmlns:rendering="http://playerstage.sourceforge.net/gazebo/xmlschema/#rendering" xmlns:sensor="http://playerstage.sourceforge.net/gazebo/xmlschema/#sensor" xmlns:xacro="http://ros.org/wiki/xacro" xmlns:xi="http://www.w3.org/2001/XInclude">
  <link name="base_footprint">
    <visual>
      <origin rpy="0 0 0" xyz="0 0 0"/>
      <geometry>
        <box size="0.001 0.001 0.001"/>
      </geometry>
    </visual>
  </link>
  <joint name="base_footprint_joint" type="fixed">
    <origin rpy="0 0 0" xyz="0 0 0"/>
    <parent link="base_footprint"/>
    <child link="base_link"/>
  </joint>
  <link name="base_link">
    <inertial>
      <origin xyz="0 0 0.055"/>
      <mass value="1.0"/>
      <inertia ixx="1.0" ixy="0.0" ixz="0.0" iyy="1.0" iyz="0.0" izz="1.0"/>
    </inertial>
    <visual>
      <geometry>
        <box size="0.25 0.16 0.02"/>
      </geometry>
      <origin rpy="0 0 0" xyz="0 0 0.055"/>
      <material name="blue">
        <color rgba="0 0 0.8 1"/>
      </material>
    </visual>
    <collision>
      <origin rpy="0 0 0" xyz="0 0 0.055"/>
      <geometry>
        <box size="0.25 0.16 0.05"/>
      </geometry>
      <inertial>
        <mass value="20"/>
        <inertia ixx="0.00533333333333" ixy="0" ixz="0" iyy="0.00833333333333" iyz="0" izz="0.0666666666667"/>
      </inertial>
    </collision>
  </link>
  <link name="left_front_wheel">
    <inertial>
      <origin xyz="0.08 0.08 0.025"/>
      <mass value="0.1"/>
      <inertia ixx="1.0" ixy="0.0" ixz="0.0" iyy="1.0" iyz="0.0" izz="1.0"/>
    </inertial>
    <visual>
      <geometry>
        <cylinder length="0.02" radius="0.025"/>
      </geometry>
      <material name="black">
        <color rgba="0 0 0 1"/>
      </material>
    </visual>
    <collision>
      <origin rpy="0 1.57075 1.57075" xyz="0.08 0.08 0.025"/>
      <geometry>
        <cylinder length="0.02" radius="0.025"/>
      </geometry>
      <inertial>
        <mass value="2"/>
        <inertia ixx="0.000379166666667" ixy="0" ixz="0" iyy="0.000379166666667" iyz="0" izz="0.000625"/>
      </inertial>
    </collision>
  </link>
  <!--
  	<joint name="left_front_wheel_joint" type="continuous">  
    	<axis xyz="0 0 1"/>  
    	<parent link="base_link"/>  
    	<child link="left_front_wheel"/>  
    	<origin rpy="0 1.57075 1.57075" xyz="0.08 0.08 0.025"/>  
    	<limit effort="100" velocity="100"/>  
    	<joint_properties damping="0.0" friction="0.0"/>  
  	</joint> -->
  <link name="right_front_wheel">
    <inertial>
      <origin xyz="0.08 -0.08 0.025"/>
      <mass value="0.1"/>
      <inertia ixx="1.0" ixy="0.0" ixz="0.0" iyy="1.0" iyz="0.0" izz="1.0"/>
    </inertial>
    <visual>
      <geometry>
        <cylinder length="0.02" radius="0.025"/>
      </geometry>
      <material name="black">
        <color rgba="0 0 0 1"/>
      </material>
    </visual>
    <collision>
      <origin rpy="0 1.57075 1.57075" xyz="0.08 -0.08 0.025"/>
      <geometry>
        <cylinder length=".02" radius="0.025"/>
      </geometry>
      <inertial>
        <mass value="2"/>
        <inertia ixx="0.000379166666667" ixy="0" ixz="0" iyy="0.000379166666667" iyz="0" izz="0.000625"/>
      </inertial>
    </collision>
  </link>
  <!-- 
  	<joint name="right_front_wheel_joint" type="continuous">  
    	<axis xyz="0 0 1"/>  
    	<parent link="base_link"/>  
    	<child link="right_front_wheel"/>  
    	<origin rpy="0 1.57075 1.57075" xyz="0.08 -0.08 0.025"/>  
    	<limit effort="100" velocity="100"/>  
    	<joint_properties damping="0.0" friction="0.0"/>  
 	</joint>   -->
  <link name="left_back_wheel">
    <inertial>
      <origin xyz="-0.08 0.08 0.025"/>
      <mass value="0.1"/>
      <inertia ixx="1.0" ixy="0.0" ixz="0.0" iyy="1.0" iyz="0.0" izz="1.0"/>
    </inertial>
    <visual>
      <geometry>
        <cylinder length=".02" radius="0.025"/>
      </geometry>
      <material name="black">
        <color rgba="0 0 0 1"/>
      </material>
    </visual>
    <collision>
      <origin rpy="0 1.57075 1.57075" xyz="-0.08 0.08 0.025"/>
      <geometry>
        <cylinder length=".02" radius="0.025"/>
      </geometry>
      <inertial>
        <mass value="2"/>
        <inertia ixx="0.000379166666667" ixy="0" ixz="0" iyy="0.000379166666667" iyz="0" izz="0.000625"/>
      </inertial>
    </collision>
  </link>
  <joint name="left_back_wheel_joint" type="continuous">
    <axis xyz="0 0 1"/>
    <parent link="base_link"/>
    <child link="left_back_wheel"/>
    <origin rpy="0 1.57075 1.57075" xyz="-0.08 0.08 0.025"/>
    <limit effort="100" velocity="100"/>
    <joint_properties damping="0.0" friction="0.0"/>
  </joint>
  <link name="right_back_wheel">
    <inertial>
      <origin xyz="-0.08 -0.08 0.025"/>
      <mass value="0.1"/>
      <inertia ixx="1.0" ixy="0.0" ixz="0.0" iyy="1.0" iyz="0.0" izz="1.0"/>
    </inertial>
    <visual>
      <geometry>
        <cylinder length=".02" radius="0.025"/>
      </geometry>
      <material name="black">
        <color rgba="0 0 0 1"/>
      </material>
    </visual>
    <collision>
      <origin rpy="0 1.57075 1.57075" xyz="-0.08 -0.08 0.025"/>
      <geometry>
        <cylinder length=".02" radius="0.025"/>
      </geometry>
      <inertial>
        <mass value="2"/>
        <inertia ixx="0.000379166666667" ixy="0" ixz="0" iyy="0.000379166666667" iyz="0" izz="0.000625"/>
      </inertial>
    </collision>
  </link>
  <joint name="right_back_wheel_joint" type="continuous">
    <axis xyz="0 0 1"/>
    <parent link="base_link"/>
    <child link="right_back_wheel"/>
    <origin rpy="0 1.57075 1.57075" xyz="-0.08 -0.08 0.025"/>
    <limit effort="100" velocity="100"/>
    <joint_properties damping="0.0" friction="0.0"/>
  </joint>
  <!-- Set the left_bridge -->
  <link name="left_bridge">
    <inertial>
      <origin xyz="-0.06 0 -0.06"/>
      <mass value="0.1"/>
      <inertia ixx="1.0" ixy="0.0" ixz="0.0" iyy="1.0" iyz="0.0" izz="1.0"/>
    </inertial>
    <visual>
      <geometry>
        <box size="0.005 0.01 0.003"/>
      </geometry>
      <material name="red">
        <color rgba="1 0 0 1"/>
      </material>
    </visual>
    <collision>
      <geometry>
        <box size="0.005 0.01 0.003"/>
      </geometry>
      <inertial>
        <mass value="0.1"/>
        <inertia ixx="2.5e-07" ixy="0" ixz="0" iyy="1.25e-07" iyz="0" izz="4.16666666667e-07"/>
      </inertial>
    </collision>
  </link>
  <!-- Set the joint connecting the left_front_wheel and bridge -->
  <joint name="left_bridge_to_bridge" type="revolute">
    <parent link="camera_link"/>
    <child link="left_bridge"/>
    <origin rpy="0 0 1.57075" xyz="-0.035 -0.06 -0.055"/>
    <axis xyz="0 0 -1"/>
    <limit effort="2.5" lower="-0.785" upper="0.785" velocity="0.1"/>
  </joint>
  <!-- Set the right_bridge -->
  <link name="right_bridge">
    <inertial>
      <origin xyz="0.06 0 -0.06"/>
      <mass value="0.1"/>
      <inertia ixx="1.0" ixy="0.0" ixz="0.0" iyy="1.0" iyz="0.0" izz="1.0"/>
    </inertial>
    <visual>
      <geometry>
        <box size="0.005 0.01 0.003"/>
      </geometry>
      <material name="red">
        <color rgba="1 0 0 1"/>
      </material>
    </visual>
    <collision>
      <origin xyz="0.06 0 -0.06"/>
      <geometry>
        <box size="0.005 0.01 0.003"/>
      </geometry>
      <inertial>
        <mass value="0.1"/>
        <inertia ixx="2.5e-07" ixy="0" ixz="0" iyy="1.25e-07" iyz="0" izz="4.16666666667e-07"/>
      </inertial>
    </collision>
  </link>
  <!-- Set the joint connecting the left_front_wheel and bridge -->
  <joint name="right_bridge_to_bridge" type="revolute">
    <parent link="camera_link"/>
    <child link="right_bridge"/>
    <origin rpy="0 0 1.57075" xyz="-0.035 0.06 -0.055"/>
    <axis xyz="0 0 -1"/>
    <limit effort="2.5" lower="-0.785" upper="0.785" velocity="0.1"/>
  </joint>
  <!-- Set the joint connecting the right_front_wheel and bridge -->
  <joint name="right_front_wheel_to_bridge" type="continuous">
    <axis xyz="0 0 1"/>
    <parent link="right_bridge"/>
    <child link="right_front_wheel"/>
    <origin rpy="0 1.57075 0" xyz="0.02 0 0"/>
    <limit effort="100" velocity="100"/>
    <joint_properties damping="0.0" friction="0.0"/>
  </joint>
  <!-- Set the joint connecting the left_front_wheel and bridge -->
  <joint name="left_front_wheel_to_bridge" type="continuous">
    <axis xyz="0 0 1"/>
    <parent link="left_bridge"/>
    <child link="left_front_wheel"/>
    <origin rpy="0 1.57075 0" xyz="-0.02 0 0"/>
    <limit effort="100" velocity="100"/>
    <joint_properties damping="0.0" friction="0.0"/>
  </joint>
  <link name="camera_link">
    <inertial>
      <origin xyz="0.115 0 0.08"/>
      <mass value="0.1"/>
      <inertia ixx="1.0" ixy="0.0" ixz="0.0" iyy="1.0" iyz="0.0" izz="1.0"/>
    </inertial>
    <visual>
      <geometry>
        <box size=".005 .03 .03"/>
      </geometry>
      <material name="white">
        <color rgba="1 1 1 1"/>
      </material>
    </visual>
    <collision>
      <origin xyz="0.115 0 0.08"/>
      <geometry>
        <box size=".005 .03 .03"/>
      </geometry>
      <inertial>
        <mass value="0.8"/>
        <inertia ixx="6e-05" ixy="0" ixz="0" iyy="1e-05" iyz="0" izz="1e-05"/>
      </inertial>
    </collision>
  </link>
  <joint name="tobox" type="fixed">
    <parent link="base_link"/>
    <child link="camera_link"/>
    <origin xyz="0.115 0 0.08"/>
  </joint>
  <joint name="carriage_front_joint" type="fixed">
    <origin rpy="0 0 0" xyz="0.04 0 0.075"/>
    <parent link="base_link"/>
    <child link="carriage_front"/>
  </joint>
  <link name="carriage_front">
    <visual>
      <origin rpy="0 0 0" xyz=" 0 0 0 "/>
      <geometry>
        <cylinder length="0.025" radius="0.004"/>
      </geometry>
      <material name="black">
        <color rgba="0 0 0 1"/>
      </material>
    </visual>
    <collision>
      <origin xyz="0.04 0 0.075"/>
      <geometry>
        <cylinder length="0.025" radius="0.004"/>
      </geometry>
      <inertial>
        <mass value="0.6"/>
        <inertia ixx="3.365e-05" ixy="0" ixz="0" iyy="3.365e-05" iyz="0" izz="4.8e-06"/>
      </inertial>
    </collision>
  </link>
  <joint name="carriage_left_joint" type="fixed">
    <origin rpy="0 0 0" xyz="0 -0.04 0.075"/>
    <parent link="base_link"/>
    <child link="carriage_left"/>
  </joint>
  <link name="carriage_left">
    <visual>
      <origin rpy="0 0 0" xyz=" 0 0 0 "/>
      <geometry>
        <cylinder length="0.025" radius="0.004"/>
      </geometry>
      <material name="black">
        <color rgba="0 0 0 1"/>
      </material>
    </visual>
    <collision>
      <origin xyz="0 -0.04 0.075"/>
      <geometry>
        <cylinder length="0.025" radius="0.004"/>
      </geometry>
      <inertial>
        <mass value="0.6"/>
        <inertia ixx="3.365e-05" ixy="0" ixz="0" iyy="3.365e-05" iyz="0" izz="4.8e-06"/>
      </inertial>
    </collision>
  </link>
  <joint name="carriage_right_joint" type="fixed">
    <origin rpy="0 0 0" xyz="0 0.04 0.075"/>
    <parent link="base_link"/>
    <child link="carriage_right"/>
  </joint>
  <link name="carriage_right">
    <visual>
      <origin rpy="0 0 0" xyz=" 0 0 0 "/>
      <geometry>
        <cylinder length="0.025" radius="0.004"/>
      </geometry>
      <material name="black">
        <color rgba="0 0 0 1"/>
      </material>
    </visual>
    <collision>
      <origin xyz="0 0.04 0.075"/>
      <geometry>
        <cylinder length="0.025" radius="0.004"/>
      </geometry>
      <inertial>
        <mass value="0.6"/>
        <inertia ixx="3.365e-05" ixy="0" ixz="0" iyy="3.365e-05" iyz="0" izz="4.8e-06"/>
      </inertial>
    </collision>
  </link>
  <joint name="carriage_back_joint" type="fixed">
    <origin rpy="0 0 0" xyz="-0.04 0 0.075"/>
    <parent link="base_link"/>
    <child link="carriage_back"/>
  </joint>
  <link name="carriage_back">
    <visual>
      <origin rpy="0 0 0" xyz=" 0 0 0 "/>
      <geometry>
        <cylinder length="0.025" radius="0.004"/>
      </geometry>
      <material name="black">
        <color rgba="0 0 0 1"/>
      </material>
    </visual>
    <collision>
      <origin xyz="-0.04 0 0.075"/>
      <geometry>
        <cylinder length="0.025" radius="0.004"/>
      </geometry>
      <inertial>
        <mass value="0.6"/>
        <inertia ixx="3.365e-05" ixy="0" ixz="0" iyy="3.365e-05" iyz="0" izz="4.8e-06"/>
      </inertial>
    </collision>
  </link>
  <link name="laser_link">
    <visual>
      <origin rpy="0 0 0" xyz=" 0 0 0 "/>
      <geometry>
        <cylinder length="0.05" radius="0.05"/>
      </geometry>
      <material name="black">
        <color rgba="0 0 0 1"/>
      </material>
    </visual>
    <collision>
      <origin xyz="0 0 0.11"/>
      <geometry>
        <cylinder length="0.05" radius="0.05"/>
      </geometry>
      <inertial>
        <mass value="2"/>
        <inertia ixx="0.00166666666667" ixy="0" ixz="0" iyy="0.00166666666667" iyz="0" izz="0.0025"/>
      </inertial>
    </collision>
  </link>
  <joint name="laser_joint" type="fixed">
    <origin rpy="0 0 0" xyz="0 0 0.11"/>
    <parent link="base_link"/>
    <child link="laser_link"/>
  </joint>
  <link name="Raspberry_Pi">
    <inertial>
      <origin xyz="-0.09 0 0.075"/>
      <mass value="0.1"/>
      <inertia ixx="1.0" ixy="0.0" ixz="0.0" iyy="1.0" iyz="0.0" izz="1.0"/>
    </inertial>
    <visual>
      <geometry>
        <box size=".055 .105 .02"/>
      </geometry>
      <material name="white">
        <color rgba="1 1 1 1"/>
      </material>
    </visual>
    <collision>
      <origin xyz="-0.09 0 0.075"/>
      <geometry>
        <box size=".055 .105 .02"/>
      </geometry>
      <inertial>
        <mass value="1.8"/>
        <inertia ixx="0.000315" ixy="0" ixz="0" iyy="0.000165" iyz="0" izz="0.00086625"/>
      </inertial>
    </collision>
  </link>
  <joint name="Raspberry_Pi_joint" type="fixed">
    <parent link="base_link"/>
    <child link="Raspberry_Pi"/>
    <origin xyz="-0.09 0 0.075"/>
  </joint>
  <gazebo reference="base_link">
    <material>Gazebo/Blue</material>
  </gazebo>
  <gazebo reference="right_front_wheel">
    <material>Gazebo/FlatBlack</material>
  </gazebo>
  <gazebo reference="right_back_wheel">
    <material>Gazebo/FlatBlack</material>
  </gazebo>
  <gazebo reference="left_front_wheel">
    <material>Gazebo/FlatBlack</material>
  </gazebo>
  <gazebo reference="left_back_wheel">
    <material>Gazebo/FlatBlack</material>
  </gazebo>
  <gazebo reference="left_bridge">
    <material>Gazebo/Red</material>
  </gazebo>
  <gazebo reference="right_bridge">
    <material>Gazebo/Red</material>
  </gazebo>
  <gazebo reference="camera_link">
    <material>Gazebo/White</material>
  </gazebo>
  <gazebo reference="carriage_front">
    <material>Gazebo/FlatBlack</material>
  </gazebo>
  <gazebo reference="carriage_left">
    <material>Gazebo/FlatBlack</material>
  </gazebo>
  <gazebo reference="carriage_right">
    <material>Gazebo/FlatBlack</material>
  </gazebo>
  <gazebo reference="carriage_back">
    <material>Gazebo/FlatBlack</material>
  </gazebo>
  <gazebo reference="laser_link">
    <material>Gazebo/FlatBlack</material>
  </gazebo>
  <gazebo reference="Raspberry_Pi">
    <material>Gazebo/White</material>
  </gazebo>
  <gazebo reference="base_footprint">
    <turnGravityOff>false</turnGravityOff>
  </gazebo>
  <gazebo>
    <plugin filename="libgazebo_ros_diff_drive.so" name="differential_drive_controller">
      <rosDebugLevel>Debug</rosDebugLevel>
      <publishWheelTF>true</publishWheelTF>
      <robotNamespace>/</robotNamespace>
      <publishTf>1</publishTf>
      <publishWheelJointState>true</publishWheelJointState>
      <alwaysOn>true</alwaysOn>
      <updateRate>100.0</updateRate>
      <legacyMode>true</legacyMode>
      <leftJoint>left_back_wheel_joint</leftJoint>
      <rightJoint>right_back_wheel_joint</rightJoint>
      <wheelSeparation>0.16</wheelSeparation>
      <wheelDiameter>0.05</wheelDiameter>
      <broadcastTF>1</broadcastTF>
      <wheelTorque>30</wheelTorque>
      <wheelAcceleration>1.8</wheelAcceleration>
      <commandTopic>cmd_vel</commandTopic>
      <odometryFrame>odom</odometryFrame>
      <odometryTopic>odom</odometryTopic>
      <robotBaseFrame>base_footprint</robotBaseFrame>
    </plugin>
  </gazebo>
  <!-- Transmission is important to link the joints and the controller -->
  <transmission name="right_front_wheel_joint_trans">
    <type>transmission_interface/SimpleTransmission</type>
    <joint name="right_front_wheel_joint">
      <hardwareInterface>hardware_interface/VelocityJointInterface</hardwareInterface>
    </joint>
    <actuator name="right_front_wheel_joint_motor">
      <hardwareInterface>hardware_interface/VelocityJointInterface</hardwareInterface>
      <mechanicalReduction>1</mechanicalReduction>
    </actuator>
  </transmission>
  <transmission name="right_back_wheel_joint_trans">
    <type>transmission_interface/SimpleTransmission</type>
    <joint name="right_back_wheel_joint">
      <hardwareInterface>hardware_interface/VelocityJointInterface</hardwareInterface>
    </joint>
    <actuator name="right_back_wheel_joint_motor">
      <hardwareInterface>hardware_interface/VelocityJointInterface</hardwareInterface>
      <mechanicalReduction>1</mechanicalReduction>
    </actuator>
  </transmission>
  <transmission name="left_front_wheel_joint_trans">
    <type>transmission_interface/SimpleTransmission</type>
    <joint name="left_front_wheel_joint">
      <hardwareInterface>hardware_interface/VelocityJointInterface</hardwareInterface>
    </joint>
    <actuator name="left_front_wheel_joint_motor">
      <hardwareInterface>hardware_interface/VelocityJointInterface</hardwareInterface>
      <mechanicalReduction>1</mechanicalReduction>
    </actuator>
  </transmission>
  <transmission name="left_back_wheel_joint_trans">
    <type>transmission_interface/SimpleTransmission</type>
    <joint name="left_back_wheel_joint">
      <hardwareInterface>hardware_interface/VelocityJointInterface</hardwareInterface>
    </joint>
    <actuator name="left_back_wheel_joint_motor">
      <hardwareInterface>hardware_interface/VelocityJointInterface</hardwareInterface>
      <mechanicalReduction>1</mechanicalReduction>
    </actuator>
  </transmission>
</robot>

